<?xml version="1.0" encoding="UTF-8"?>
<!-- Generated by org.testng.reporters.JUnitXMLReporter -->
<testsuite hostname="SG-L-7301093" ignored="0" name="Default test(failed)" tests="2" failures="2" timestamp="2022-05-21T19:24:30 SGT" time="0.043" errors="0">
  <testcase name="userLogin1" time="0.009" classname="com.Maven_Tester_SelfExercise.Tester_Code">
    <failure type="java.lang.AssertionError" message="LogIn Failed expected [0] but found [1]">
      <![CDATA[java.lang.AssertionError: LogIn Failed expected [0] but found [1]
at com.Maven_Tester_SelfExercise.Tester_Code.userLogin1(Tester_Code.java:16)
at java.util.ArrayList.forEach(Unknown Source)
... Removed 32 stack frames]]>
    </failure>
  </testcase> <!-- userLogin1 -->
  <testcase name="userLogin2" time="0.001" classname="com.Maven_Tester_SelfExercise.Tester_Code">
    <failure type="java.lang.AssertionError" message="LogIn Failed expected [1] but found [0]">
      <![CDATA[java.lang.AssertionError: LogIn Failed expected [1] but found [0]
at com.Maven_Tester_SelfExercise.Tester_Code.userLogin2(Tester_Code.java:24)
at java.util.ArrayList.forEach(Unknown Source)
... Removed 32 stack frames]]>
    </failure>
  </testcase> <!-- userLogin2 -->
</testsuite> <!-- Default test(failed) -->
